Workbook

Sheet Summary
H2: On PO | I2: Drawing app | J2: Ready to ship | K2: Commissioning
B3: Hardware | C3: =+RO!G58 -> 45246.97 | D3: =+RO!I58 -> 71942.682 | E3: =+RO!I59 -> 26695.712 | F3: =+RO!I60 -> 0.37106918 | H3: 0.6 | I3: 0.2 | J3: 0.15 | K3: 0.05 | L3: =SUM(H3:K3) -> 1
B4: Labour | C4: =+Labour!G51 -> 7065 | D4: =+Labour!I51 -> 11589.426 | E4: =+Labour!I52 -> 4524.426 | F4: =+Labour!I53 -> 0.39039259 | H4: =+D5*$H$3 -> 50119.265 | I4: =+D5*$I$3 -> 16706.422 | J4: =+D5*$J$3 -> 12529.816 | K4: =+D5*$K$3 -> 4176.6054 | L4: =SUM(H4:K4) -> 83532.108
C5: =SUM(C3:C4) -> 52311.97 | D5: =SUM(D3:D4) -> 83532.108 | E5: =SUM(E3:E4) -> 31220.138 | F5: =AVERAGE(F3:F4) -> 0.38073088 | H5: =SUM(H4:H4) -> 50119.265 | I5: =SUM(I4:I4) -> 16706.422 | J5: =SUM(J4:J4) -> 12529.816 | K5: =SUM(K4:K4) -> 4176.6054 | L5: =SUM(L4:L4) -> 83532.108
C6: 75640 | D6: =+C6-D5 -> -7892.1083

Sheet RO
B3: Estimate sheet. | J3: Project Management Sheet
A4: Customer: | C4: CSS Renewables | G4: Quote No: | J4: SO No: | K4: SOXXXX
G5: Originator: | H5: Sisman | J5: Customer's P.O.: | K5: [PO_Number]
A6: Description: | G6: Date: | J6: Contact: | K6: [Contact_Name]
G7: Contact: | J7: Sales Value:
B8: Qty: | C8: Item: | D8: Supplier: | E8: Part no: | F8: Estimated price: (each) | G8: Estimated price: (total) | H8: % | I8: Total sell price: | J8: Supplier: | K8: P.O. no.: | L8: Date: | M8: P.O. value: | N8: Est. delivery: | O8: Date delivered:
B10: Equipment:
E11: m3/hr | G11: =F11*B11 -> 0 | I11: =((H11/100)+1)*G11 -> 0
B12: 1 | C12: RO MO3 | D12: J&F - Ecosoft | E12: 4m3/hr | F12: 9400 | G12: =F12*B12 -> 9400 | H12: 50 | I12: =((H12/100)+1)*G12 -> 14100
B13: 1 | C13: RO MO2 | D13: J&F - Ecosoft | F13: 7583 | G13: =F13*B13 -> 7583 | H13: =+H12 -> 50 | I13: =((H13/100)+1)*G13 -> 11374.5
B14: 1 | C14: Permeate Rinsing Option for MO1-MO4 | D14: J&F - Ecosoft | F14: 434 | G14: =F14*B14 -> 434 | H14: =+H13 -> 50 | I14: =((H14/100)+1)*G14 -> 651
B15: 5 | C15: RO Membranes | D15: J&F - Ecosoft | F15: 884 | G15: =F15*B15 -> 4420 | H15: =+H14 -> 50 | I15: =((H15/100)+1)*G15 -> 6630
B16: 1 | C16: 14" x 65" Tank Kit, 1" Distributor Head c/w De-min | D16: J&F - Ecosoft | F16: 600 | G16: =F16*B16 -> 600 | H16: =+H15 -> 50 | I16: =((H16/100)+1)*G16 -> 900
B17: 2 | C17: 1" Bypass Valve | D17: J&F - Ecosoft | F17: 23 | G17: =F17*B17 -> 46 | H17: =+H16 -> 50 | I17: =((H17/100)+1)*G17 -> 69
C18: Perm Flush | D18: J&F - Ecosoft | F18: 435 | G18: =F18*B18 -> 0 | H18: =+H17 -> 50 | I18: =((H18/100)+1)*G18 -> 0
B19: 1 | C19: Shipping | D19: J&F - Ecosoft | F19: 650 | G19: =F19*B19 -> 650 | H19: =+H18 -> 50 | I19: =((H19/100)+1)*G19 -> 975
B20: 2 | C20: 18 x 65 CIF Carbon Unit | D20: J&F - Ecosoft | F20: 1062 | G20: =F20*B20 -> 2124 | H20: =+H19 -> 50 | I20: =((H20/100)+1)*G20 -> 3186
B21: 2 | C21: 1" Bypass Valve | D21: J&F - Ecosoft | F21: 23 | G21: =F21*B21 -> 46 | H21: =+H20 -> 50 | I21: =((H21/100)+1)*G21 -> 69
B22: 2 | C22: WS1 No Hard Water Bypass Valve - F x Male | D22: J&F - Ecosoft | F22: 100 | G22: =F22*B22 -> 200 | H22: =+H21 -> 50 | I22: =((H22/100)+1)*G22 -> 300
B23: 1 | C23: WS1 Bypass Adaptor Assembly | D23: J&F - Ecosoft | F23: 13.97 | G23: =F23*B23 -> 13.97 | H23: =+H22 -> 50 | I23: =((H23/100)+1)*G23 -> 20.955
B24: 2 | C24: Dosing station Grundomat DDC120 | D24: J&F - Ecosoft | F24: 900 | G24: =F24*B24 -> 1800 | H24: =+H23 -> 50 | I24: =((H24/100)+1)*G24 -> 2700
C25: NaOH (sodium hydroxide) dosing | D25: J&F - Ecosoft | F25: 900 | G25: =F25*B25 -> 0 | H25: =+H24 -> 50 | I25: =((H25/100)+1)*G25 -> 0
B26: 25 | C26: Chemicals | D26: J&F - Ecosoft | F26: 5 | G26: =F26*B26 -> 125 | H26: =+H25 -> 50 | I26: =((H26/100)+1)*G26 -> 187.5
B27: 1 | C27: pH Controler | D27: AWE | F27: 1100 | G27: =F27*B27 -> 1100 | H27: =+H26 -> 50 | I27: =((H27/100)+1)*G27 -> 1650
B28: 1 | C28: Enduramaxx 10000 Litre Vertical Potable Water Tank | F28: 1100 | G28: =F28*B28 -> 1100 | H28: =+H27 -> 50 | I28: =((H28/100)+1)*G28 -> 1650
B29: 1 | C29: Enduramaxx 5000 Litre Vertical Potable Water Tank | F29: 812 | G29: =F29*B29 -> 812 | H29: =+H28 -> 50 | I29: =((H29/100)+1)*G29 -> 1218
C30: Transfer Pump | F30: 1200 | G30: =F30*B30 -> 0 | H30: =+H29 -> 50 | I30: =((H30/100)+1)*G30 -> 0
C33: Ion Exchange | D33: J&F - Ecosoft | F33: 600 | G33: =F33*B33 -> 0 | H33: =+H26 -> 50 | I33: =((H33/100)+1)*G33 -> 0
C34: Delivery | F34: 650 | G34: =F34*B34 -> 0 | H34: =+H33 -> 50 | I34: =((H34/100)+1)*G34 -> 0
B35: 1 | C35: Materials Assembley / Pipework | F35: 4500 | G35: =F35*B35 -> 4500 | H35: =+H33 -> 50 | I35: =((H35/100)+1)*G35 -> 6750
B36: 1 | C36: Buffer Tanks | E36: 5 m3 | F36: 392 | G36: =F36*B36 -> 392 | H36: =+H35 -> 50 | I36: =((H36/100)+1)*G36 -> 588
B37: 3 | C37: Booster/Transfer pump | F37: 1867 | G37: =F37*B37 -> 5601 | H37: =+H36 -> 50 | I37: =((H37/100)+1)*G37 -> 8401.5
C38: Electical | F38: 2000 | G38: =F38*B38 -> 0 | H38: =+H37 -> 50 | I38: =((H38/100)+1)*G38 -> 0
C39: Delivery | F39: 700 | G39: =F39*B39 -> 0 | H39: =+H38 -> 50 | I39: =((H39/100)+1)*G39 -> 0
B40: Labour:
G41: =F41*B41 -> 0 | I41: =((H41/100)+1)*G41 -> 0
C42: On site - mechanical | D42: man days | F42: 350 | G42: =F42*B42 -> 0 | H42: =+H15 -> 50 | I42: =((H42/100)+1)*G42 -> 0
C43: On site - electrical | D43: man days | F43: 350 | G43: =F43*B43 -> 0 | H43: =+H42 -> 50 | I43: =((H43/100)+1)*G43 -> 0
C44: Milaege | D44: £0.45 per mile | F44: 0.45 | G44: =F44*B44 -> 0 | H44: =+H43 -> 50 | I44: =((H44/100)+1)*G44 -> 0
C45: Overnight Accomodation | D45: Hotel Rooms | F45: 100 | G45: =F45*B45 -> 0 | H45: =+H44 -> 50 | I45: =((H45/100)+1)*G45 -> 0
...

Sheet Labour
B3: Estimate sheet. | J3: Project Management Sheet
A4: Customer: | C4: CSS Renewables | G4: Quote No: | J4: SO No: | K4: SOXXXX
G5: Originator: | H5: Sisman | J5: Customer's P.O.: | K5: [PO_Number]
A6: Description: | G6: Date: | J6: Contact: | K6: [Contact_Name]
G7: Contact: | J7: Sales Value:
B8: Qty: | C8: Item: | D8: Supplier: | E8: Part no: | F8: Estimated price: (each) | G8: Estimated price: (total) | H8: % | I8: Total sell price: | J8: Supplier: | K8: P.O. no.: | L8: Date: | M8: P.O. value: | N8: Est. delivery: | O8: Date delivered:
B10: Equipment:
E11: m3/hr | G11: =F11*B11 -> 0 | I11: =((H11/100)+1)*G11 -> 0
B12: 0 | C12: RO MO3 | D12: J&F - Ecosoft | E12: 4m3/hr | F12: 9400 | G12: =F12*B12 -> 0 | H12: 50 | I12: =((H12/100)+1)*F12*B12 -> 0
B13: 0 | C13: RO MO2 | F13: 7583 | G13: =F13*B13 -> 0 | H13: =+H12 -> 50 | I13: =((H13/100)+1)*F13*B13 -> 0
B14: 0 | C14: Permeate Rinsing Option for MO1-MO4 | F14: 434 | G14: =F14*B14 -> 0 | H14: =+H13 -> 50 | I14: =((H14/100)+1)*F14*B14 -> 0
B15: 0 | C15: RO Membranes | D15: J&F - Ecosoft | F15: 884 | G15: =F15*B15 -> 0 | H15: =+H14 -> 50 | I15: =((H15/100)+1)*F15*B15 -> 0
B16: 0 | C16: 14" x 65" Tank Kit, 1" Distributor Head c/w De-min | F16: 600 | G16: =F16*B16 -> 0 | H16: =+H15 -> 50 | I16: =((H16/100)+1)*F16*B16 -> 0
B17: 0 | C17: 1" Bypass Valve | F17: 23 | G17: =F17*B17 -> 0 | H17: =+H16 -> 50 | I17: =((H17/100)+1)*F17*B17 -> 0
B18: 0 | C18: Perm Flush | D18: J&F - Ecosoft | F18: 435 | G18: =F18*B18 -> 0 | H18: =+H17 -> 50 | I18: =((H18/100)+1)*F18*B18 -> 0
B19: 0 | C19: Shipping | D19: J&F - Ecosoft | F19: 650 | G19: =F19*B19 -> 0 | H19: =+H18 -> 50 | I19: =((H19/100)+1)*F19*B19 -> 0
B20: 0 | C20: 18 x 65 CIF Carbon Unit | D20: J&F - Ecosoft | F20: 1062 | G20: =F20*B20 -> 0 | H20: =+H19 -> 50 | I20: =((H20/100)+1)*F20*B20 -> 0
B21: 0 | C21: 1" Bypass Valve | F21: 23 | G21: =F21*B21 -> 0 | H21: =+H20 -> 50 | I21: =((H21/100)+1)*F21*B21 -> 0
B22: 0 | C22: WS1 No Hard Water Bypass Valve - F x Male | F22: 100 | G22: =F22*B22 -> 0 | H22: =+H21 -> 50 | I22: =((H22/100)+1)*F22*B22 -> 0
B23: 0 | C23: WS1 Bypass Adaptor Assembly | F23: 13.97 | G23: =F23*B23 -> 0 | H23: =+H22 -> 50 | I23: =((H23/100)+1)*F23*B23 -> 0
B24: 0 | C24: Dosing station Grundomat DDC120 | F24: 900 | G24: =F24*B24 -> 0 | H24: =+H23 -> 50 | I24: =((H24/100)+1)*F24*B24 -> 0
B25: 0 | C25: NaOH (sodium hydroxide) dosing | D25: J&F - Ecosoft | F25: 900 | G25: =F25*B25 -> 0 | H25: =+H24 -> 50 | I25: =((H25/100)+1)*F25*B25 -> 0
B26: 0 | C26: Chemicals | F26: 5 | G26: =F26*B26 -> 0 | H26: =+H25 -> 50 | I26: =((H26/100)+1)*F26*B26 -> 0
B27: 0 | C27: Ion Exchange | D27: J&F - Ecosoft | F27: 650 | G27: =F27*B27 -> 0 | H27: =+H26 -> 50 | I27: =((H27/100)+1)*F27*B27 -> 0
B28: 0 | C28: Materials Assembley / Pipework | F28: 3500 | G28: =F28*B28 -> 0 | H28: =+H27 -> 50 | I28: =((H28/100)+1)*F28*B28 -> 0
B29: 0 | C29: Buffer Tanks | E29: 5 m3 | F29: 838 | G29: =F29*B29 -> 0 | H29: =+H28 -> 50 | I29: =((H29/100)+1)*F29*B29 -> 0
B30: 0 | C30: Booster/Transfer pump | F30: 1100 | G30: =F30*B30 -> 0 | H30: =+H29 -> 50 | I30: =((H30/100)+1)*F30*B30 -> 0
B31: 0 | C31: Electical | F31: 2000 | G31: =F31*B31 -> 0 | H31: =+H30 -> 50 | I31: =((H31/100)+1)*F31*B31 -> 0
B32: 0 | C32: Delivery | F32: 1000 | G32: =F32*B32 -> 0 | H32: =+H31 -> 50 | I32: =((H32/100)+1)*F32*B32 -> 0
B33: Labour:
G34: =F34*B34 -> 0 | I34: =((H34/100)+1)*G34 -> 0
B35: 12 | C35: On site - mechanical | D35: man days | F35: 325 | G35: =F35*B35 -> 3900 | H35: =+H15 -> 50 | I35: =((H35/100)+1)*G35 -> 5850
B36: 5 | C36: On site - electrical | D36: man days | F36: 325 | H36: =+H35 -> 50 | I36: =((H36/100)+1)*G36 -> 0
B37: 1200 | C37: Milaege | D37: £0.45 per mile | F37: 0.45 | G37: =F37*B37 -> 540 | H37: =+H36 -> 50 | I37: =((H37/100)+1)*G37 -> 810
B38: 12 | C38: Overnight Accomodation | D38: Hotel Rooms | F38: 125 | G38: =F38*B38 -> 1500 | H38: =+H37 -> 50 | I38: =((H38/100)+1)*G38 -> 2250
B39: 0 | C39: Commissioning | D39: man days | F39: 350 | G39: =F39*B39 -> 0 | H39: =+H38 -> 50 | I39: =((H39/100)+1)*G39 -> 0
B40: 1 | C40: Site surveys | D40: man days | F40: 350 | G40: =F40*B40 -> 350 | H40: =+H39 -> 50 | I40: =((H40/100)+1)*G40 -> 525
B41: 2 | C41: Site management | D41: man days | F41: 350 | G41: =F41*B41 -> 700 | H41: =+H40 -> 50 | I41: =((H41/100)+1)*G41 -> 1050
C42: Design | D42: man days | F42: 400 | G42: =F42*B42 -> 0 | H42: =+H41 -> 50 | I42: =((H42/100)+1)*G42 -> 0
C43: Project management | D43: man days | F43: 350 | G43: =F43*B43 -> 0 | H43: =+H42 -> 50 | I43: =((H43/100)+1)*G43 -> 0
...

Sheet ecosoft Quote

Sheet P&ID

Sheet Sheet1
B3: 0 | C3: 0 | D3: 1 | E3: 2 | F3: 3 | G3: 4 | H3: 5 | I3: 6 | J3: 7 | K3: 8 | L3: 9 | M3: 10 | N3: 11 | O3: 12 | P3: 13 | Q3: 14 | R3: 15 | S3: 16 | T3: 17
B4: Order Placement Invoice
B5: Order RO
B6: Order Container
B7: FAT
